Workbook

Sheet 04-27
A1: BAIT 재고현황
G3: (2026. 04. 27. 기준) | I3: 입고 예정물량 (01/12 사입보고 件) | J3: 입고 예정물량 (04/14 사입보고 件)
A4: 품 명 | B4: BOX SIZE | D4: 재고량 | E4: 단 가 | F4: 보 관 창 고 | G4: 비 고 | I4: KERBAU(2) | J4: PAHALA(1) | K4: PAHALA(2)
A5: 인니산 무로아지 | B5: 51-60미 | C5: / 10KG | D5: ='상세재고 현황'!J7 -> 8614 | E5: $19.20 ~ $20.50 | F5: ㈜삼성냉장 | G5: - 25.12.05 / 25.12.08 / 25.12.09 / 26.01.13 / 26.03.03 / 26.04.23 / 26.04.27 입고 | I5: 0 | L5: =SUM(D5,I5:K5) -> 8614
B6: 61-70미 | D6: ='상세재고 현황'!J8 -> 701 | G6: - 26.03.03 / 26.04.23 입고 | I6: 619 | L6: =SUM(D6,I6:K6) -> 1320
B7: 71-80미 | D7: ='상세재고 현황'!J9 -> 996 | G7: - 26.03.03 / 26.04.23 입고 | I7: 531 | L7: =SUM(D7,I7:K7) -> 1527
B8: 81-90미 | D8: ='상세재고 현황'!J10 -> 731 | G8: - 26.03.03 / 26.04.23 입고 | I8: 446 | L8: =SUM(D8,I8:K8) -> 1177
B9: 91-100미 | D9: ='상세재고 현황'!J11 -> 1342 | G9: - 26.03.03 / 26.04.23 입고 | I9: 854 | L9: =SUM(D9,I9:K9) -> 2196
A10: 소 계 | D10: =SUM(D5:D9) -> 12384 | I10: =SUM(I5:I9) -> 2450 | J10: =SUM(J5:J9) -> 0 | K10: =SUM(K5:K9) -> 0 | L10: =SUM(D10,I10:K10) -> 14834
A11: 인니산 밀크피쉬 | B11: 51-60미 | C11: / 10KG | D11: ='상세재고 현황'!J20 -> 2750 | E11: $14.90 ~ $15.50 | F11: ㈜동영콜드 프라자 | G11: - 25.11.20 / 26.03.03 입고
B12: 61-70미 | D12: ='상세재고 현황'!J21 -> 2957 | G12: - 25.11.20 / 26.03.03 입고
B13: 71-80미 | D13: ='상세재고 현황'!J22 -> 1547 | G13: - 25.11.06 / 26.03.03 입고
B14: 81-90미 | D14: ='상세재고 현황'!J23 -> 1598 | G14: - 25.11.06 입고
B15: 91-100미 | D15: ='상세재고 현황'!J24 -> 1672 | G15: - 24.08.09 / 25.11.06 입고
A16: 소 계 | D16: =SUM(D11:D15) -> 10524
A17: 멕시코산 정어리 | B17: 110~130미 | C17: / 15KG | D17: ='상세재고 현황'!J61 -> 1450 | E17: $18.00 | F17: 동원산업㈜ 부산냉장센터 | G17: - 26.01.16 사입 (25.10.28 입고)
A18: 소 계 | D18: =SUM(D17:D17) -> 1450
A19: 포크산 오징어 | B19: 120미 내외 | C19: / 20KG | D19: ='상세재고 현황'!J88 -> 300 | E19: 141000 | F19: 보성냉장㈜ | G19: - 26.01.16 사입 (25.04.01 입고)
D20: ='상세재고 현황'!J89 -> 1000 | E20: 136000 | F20: 한일냉장㈜ 2공장 | G20: - 26.04.15 사입 (25.04.01 입고)
A21: 소 계 | D21: =SUM(D19:D20) -> 1300
A22: 합 계 | D22: =D16+D18+D10+D21 -> 25658

Sheet 선적 계획
A1: BAIT 재고 및 선적 계획(안)
A2: ='04-27'!G3 -> (2026. 04. 27. 기준)
P3: (단위 : C/S)
A4: 품 명 | B4: SIZE | C4: 현재고량 | D4: 사입 예정량 | F4: 사입 후 예상 합계 | H4: 선적 및 탁송 예상 수량 | N4: 선적 후 예상 잔량 | O4: 사입 예정량 | P4: 선적 후 예상 잔량
R5: `21.6월/탁송 | S5: `21.6월/탁송
M6: 소계 | R6: 신영 52호 | S6: 파나록스 506
A7: 선장명 | R7: 이현철 | S7: 박성대
A8: 인니산 무로아지 (10KG) | B8: 61-90미 | C8: ='04-27'!D10 -> 12384 | D8: 0 | E8: 0 | F8: =C8+D8+E8 -> 12384 | M8: =SUM(G8:L8) -> 0 | N8: -6730 | O8: 7800 | P8: =F8-M8 -> 12384 | R8: 1500 | S8: 1000
A9: 러시아산 정어리 (30KG) | B9: 285-330미 | C9: ='04-27'!#REF! -> #REF! | D9: 0 | E9: 0 | F9: =C9+D9+E9 -> #REF! | M9: =SUM(G9:L9) -> 0 | N9: 0 | P9: =F9-M9 -> #REF! | T9: =C9*3 -> #REF! | U9: =M9*3 -> 0 | V9: =P9*3 -> #REF!
A10: 러시아산 정어리 (20.80KG) | B10: 220미 | C10: ='04-27'!#REF! -> #REF! | D10: 0 | E10: 0 | F10: =C10+D10+E10 -> #REF! | M10: =SUM(G10:L10) -> 0 | N10: 0 | P10: =F10-M10 -> #REF! | T10: =C10*2.08 -> #REF! | U10: =M10*2.08 -> 0 | V10: =P10*2.08 -> #REF!
A11: 러시아산 정어리 (23.20KG) | B11: 220미 | C11: ='04-27'!#REF! -> #REF! | D11: 0 | E11: 0 | F11: =C11+D11+E11 -> #REF! | M11: =SUM(G11:L11) -> 0 | N11: 0 | P11: =F11-M11 -> #REF! | T11: =C11*2.08 -> #REF! | U11: =M11*2.08 -> 0 | V11: =P11*2.08 -> #REF!
A12: 포크산 오징어 (20.5KG) | B12: 125-135미 | C12: ='04-27'!#REF! -> #REF! | D12: 0 | E12: 0 | F12: =C12+D12+E12 -> #REF! | M12: =SUM(G12:L12) -> 0 | N12: 385 | O12: 0 | P12: =F12-M12 -> #REF! | T12: =SUM(T9:T10) -> #REF! | U12: =SUM(U9:U10) -> 0 | V12: =SUM(V9:V10) -> #REF!
A13: 인니산 밀크피쉬 (10KG) | B13: 51-100미 | C13: ='04-27'!D16 -> 10524 | D13: 0 | E13: 0 | F13: =C13+D13+E13 -> 10524 | M13: =SUM(G13:L13) -> 0 | N13: -3301 | O13: 4450 | P13: =F13-M13 -> 10524 | R13: 500 | S13: 500 | V13: =V12/2.3 -> #REF!
A14: 러시아산 청어 (20KG) | B14: S | C14: ='04-27'!#REF! -> #REF! | D14: 0 | E14: 0 | F14: =C14+D14+E14 -> #REF! | M14: =SUM(G14:L14) -> 0 | N14: 0 | O14: 0 | P14: =F14-M14 -> #REF!
A15: 합 계 | C15: =SUM(C8:C14) -> #REF! | D15: =SUM(D8:D14) -> 0 | E15: =SUM(E8:E14) -> 0 | F15: =C15+D15+E15 -> #REF! | G15: =SUM(G8:G14) -> 0 | H15: =SUM(H8:H14) -> 0 | I15: =SUM(I8:I14) -> 0 | J15: =SUM(J8:J14) -> 0 | K15: =SUM(K8:K14) -> 0 | L15: =SUM(L8:L14) -> 0 | M15: =SUM(M8:M14) -> 0 | N15: -10415 | O15: 22000 | P15: =F15-M15 -> #REF! | R15: =SUM(R8:R14) -> 2000 | S15: =SUM(S8:S14) -> 1500
D17: 인니산 무로아지 (10KG) | F17: 10kg 환산 | G17: =G8*1 -> 0 | H17: =H8*1 -> 0 | I17: =I8*1 -> 0 | J17: =J8*1 -> 0 | K17: =K8*1 -> 0 | L17: =L8*1 -> 0 | M17: =M8*1 -> 0
D18: 러시아산 정어리 (30KG) | G18: =G9*3 -> 0 | H18: =H9*3 -> 0 | I18: =I9*3 -> 0 | J18: =J9*3 -> 0 | K18: =K9*3 -> 0 | L18: =L9*3 -> 0 | M18: =M9*3 -> 0
D19: 러시아산 정어리 (20.80KG) | G19: =G10*2.08 -> 0 | H19: =H10*2.08 -> 0 | I19: =I10*2.08 -> 0 | J19: =J10*2.08 -> 0 | K19: =K10*2.08 -> 0 | L19: =L10*2.08 -> 0 | M19: =M10*2.08 -> 0
D20: 포크산 오징어 (20.5KG) | G20: =G12*2.05 -> 0 | H20: =H12*2.05 -> 0 | I20: =I12*2.05 -> 0 | J20: =J12*2.05 -> 0 | K20: =K12*2.05 -> 0 | L20: =L12*2.05 -> 0 | M20: =M12*2.05 -> 0
D21: 인니산 밀크피쉬 (10KG) | G21: =G13*1 -> 0 | H21: =H13*1 -> 0 | I21: =I13*1 -> 0 | J21: =J13*1 -> 0 | K21: =K13*1 -> 0 | L21: =L13*1 -> 0 | M21: =M13*1 -> 0
D22: 러시아산 청어 (20KG) | G22: =G14*2 -> 0 | H22: =H14*2 -> 0 | I22: =I14*2 -> 0 | J22: =J14*2 -> 0 | K22: =K14*2 -> 0 | L22: =L14*2 -> 0 | M22: =M14*2 -> 0
D24: 합 계 | G24: =SUM(G17:G23) -> 0 | H24: =SUM(H17:H23) -> 0 | I24: =SUM(I17:I23) -> 0 | J24: =SUM(J17:J23) -> 0 | K24: =SUM(K17:K23) -> 0 | L24: =SUM(L17:L23) -> 0 | M24: =SUM(M17:M23) -> 0

Sheet 상세재고 현황
B1: 어종별 상세 재고량
J2: ='04-27'!G3 -> (2026. 04. 27. 기준)
A3: * 인니산 무로아지(10KG) 창고별 재고량
B4: 삼성냉장 | C4: 삼성냉장 | D4: 삼성냉장 | E4: 삼성냉장 | F4: 삼성냉장 | G4: 삼성냉장 | H4: 삼성냉장
A5: 미수 | B5: 25.12.05 | C5: 25.12.08 | D5: 25.12.09 | E5: 26.01.13 | F5: 26.03.03 | G5: 26.04.23 | H5: 26.04.27 | J5: 계
A6: BL NO. | B6: ARM0421601A | C6: 440510025061 | D6: 440510024897 | E6: HDMUJKTA34257700 | F6: 440610002207 | G6: 440610004928 | H6: ARM0440967
A7: 51-60 | B7: =2450-800-1171 -> 479 | C7: =962 -> 962 | D7: =1591 -> 1591 | E7: =2002 -> 2002 | F7: =430 -> 430 | G7: =700 -> 700 | H7: =2450 -> 2450 | J7: =SUM(B7:I7) -> 8614
A8: 61-70 | C8: =602-102-500 -> 0 | D8: =566-566 -> 0 | F8: =260 -> 260 | G8: =441 -> 441 | J8: =SUM(B8:I8) -> 701
A9: 71-80 | C9: =886-532-354 -> 0 | D9: =293-293 -> 0 | E9: =182-182 -> 0 | F9: =398 -> 398 | G9: =598 -> 598 | J9: =SUM(B9:I9) -> 996
A10: 81-90 | E10: =127-127 -> 0 | F10: =434 -> 434 | G10: =297 -> 297 | J10: =SUM(B10:I10) -> 731
A11: 91-100 | E11: =139-139 -> 0 | F11: =928 -> 928 | G11: =414 -> 414 | J11: =SUM(B11:I11) -> 1342
A12: 계 | B12: =SUM(B7:B11) -> 479 | C12: =SUM(C7:C11) -> 962 | D12: =SUM(D7:D11) -> 1591 | E12: =SUM(E7:E11) -> 2002 | F12: =SUM(F7:F11) -> 2450 | G12: =SUM(G7:G11) -> 2450 | H12: =SUM(H7:H11) -> 2450 | I12: =SUM(I7:I11) -> 0 | J12: =SUM(J7:J11) -> 12384
A13: 단가 | B13: 19.9 | C13: 19.2 | D13: 19.2 | E13: 19.9 | F13: 20.5 | G13: 20.5 | H13: 20.5
B14: 외국 선박용품
A16: * 인니산 밀크피쉬(10KG) 창고별 재고량
B17: 동영콜드 | C17: 동영콜드 | D17: 동영콜드 | E17: 동영콜드 | F17: 동영콜드 | G17: 동영콜드
A18: 미수 | B18: 24.08.09 | C18: 25.11.06 | D18: 25.11.06 | E18: 25.11.20 | F18: 26.03.03 | G18: 26.03.03 | J18: 계
A19: BL NO. | B19: 440410015711 | C19: 440510022565 | D19: 440510022862 | E19: ARM0419282 | F19: ARM0432177 | G19: 440610002191
A20: 51-60 | C20: =350-350 -> 0 | D20: =349-349 -> 0 | E20: =1654-401 -> 1253 | F20: =1148 -> 1148 | G20: =349 -> 349 | J20: =SUM(B20:I20) -> 2750
A21: 61-70 | B21: =491-378-113 -> 0 | C21: =306-306 -> 0 | D21: =300-300 -> 0 | E21: =796-394 -> 402 | F21: =702 -> 702 | G21: =1853 -> 1853 | J21: =SUM(B21:I21) -> 2957
A22: 71-80 | B22: =2007-401-300-1306 -> 0 | C22: =448 -> 448 | D22: =251 -> 251 | F22: =600 -> 600 | G22: =248 -> 248 | J22: =SUM(B22:I22) -> 1547
A23: 81-90 | B23: =1401-1401 -> 0 | C23: =894 -> 894 | D23: =704 -> 704 | J23: =SUM(B23:I23) -> 1598
A24: 91-100 | B24: =1001-127-500 -> 374 | C24: =452 -> 452 | D24: =846 -> 846 | J24: =SUM(B24:I24) -> 1672
A25: 계 | B25: =SUM(B20:B24) -> 374 | C25: =SUM(C20:C24) -> 1794 | D25: =SUM(D20:D24) -> 1801 | E25: =SUM(E20:E24) -> 1655 | F25: =SUM(F20:F24) -> 2450 | G25: =SUM(G20:G24) -> 2450 | H25: =SUM(H20:H24) -> 0 | I25: =SUM(I20:I24) -> 0 | J25: =SUM(J20:J24) -> 10524
A26: 단가 | B26: 14.9 | C26: 15.5 | D26: 15.5 | E26: 15.5 | F26: 15.5 | G26: 15.5
B27: 외국 선박용품
A29: * 러시아산 정어리(20.80KG) 창고별 재고량
B30: 감천고려2
A31: 미수 | B31: 22.10.20 | J31: 계
A32: BL NO.
A33: 190-200미 | B33: =2965-1000-500-1465 -> 0 | J33: =SUM(B33:I33) -> 0
A34: 계 | B34: =SUM(B33:B33) -> 0 | J34: =SUM(J33:J33) -> 0 | M34: =1300-860 -> 440
B35: 20.8
B36: 수입통관-분증
A38: * 러시아산 정어리(23.20KG) 창고별 재고량
B39: 동원산업㈜
A40: 미수 | B40: 22.11.24 | J40: 계
A41: 285~330미 | B41: =4500-500-100-35-1500-1000-400-565-400 -> 0 | F41: =SUM(F40) -> 0 | G41: =SUM(G40) -> 0 | J41: =SUM(B41:I41) -> 0
A42: 계 | B42: =SUM(B41) -> 0 | C42: =SUM(C41) -> 0 | D42: =SUM(D41) -> 0 | E42: =SUM(E41) -> 0 | H42: =SUM(H41) -> 0 | I42: =SUM(I41) -> 0 | J42: =SUM(J41) -> 0
B43: 23.66
...

Sheet Sheet1
E9: =2904*1319.1*19 -> 72782662
E10: =2895*1273.5*19 -> 70048868
E11: =4900*1351.7*17.2 -> 113921276
E14: =1365*1240.8*23.66 -> 40072753
E15: =1885*1325.6*32.2 -> 80459943
E17: =100*15.5*1390.1 -> 2154655
E18: =100*15.5*1390.1 -> 2154655
E19: =1504*15.25*1319.2 -> 30257171
E20: =2280*15.25*1319.1 -> 45865107
E21: =4683*15.5*1276.2 -> 92634891
